Workbook
Name Slicer_Category: #N/A
Name Slicer_Customer_Segment: #N/A
Name Slicer_Payment_Method: #N/A
Name Slicer_Region: #N/A

Sheet Sheet1
A1: SUMMARY OUTPUT
A3: Regression Statistics
A4: Multiple R | B4: 0.015347018
A5: R Square | B5: 0.00023553098
A6: Adjusted R Square | B6: -0.0037957774
A7: Standard Error | B7: 1034.4107
A8: Observations | B8: 250
A10: ANOVA
B11: df | C11: SS | D11: MS | E11: F | F11: Significance F
A12: Regression | B12: 1 | C12: 62515.548 | D12: 62515.548 | E12: 0.058425443 | F12: 0.80920187
A13: Residual | B13: 248 | C13: 2.6536138e+08 | D13: 1070005.5
A14: Total | B14: 249 | C14: 2.6542389e+08
B16: Coefficients | C16: Standard Error | D16: t Stat | E16: P-value | F16: Lower 95% | G16: Upper 95% | H16: Lower 95.0% | I16: Upper 95.0%
A17: Intercept | B17: 951.6427 | C17: 158.41342 | D17: 6.0073363 | E17: 6.6824753e-09 | F17: 639.63548 | G17: 1263.6499 | H17: 639.63548 | I17: 1263.6499
A18: Customer Tenure | B18: -0.048982803 | C18: 0.20264814 | D18: -0.24171356 | E18: 0.80920187 | F18: -0.44811365 | G18: 0.35014804 | H18: -0.44811365 | I18: 0.35014804

Sheet Raw Data
A1: 📊 PR. Final Project — Customer Transaction Raw Data
A4: Transaction_ID | B4: Date | C4: Customer_ID | D4: Customer_Name | E4: Product_ID | F4: Product_Name | G4: Category | H4: Quantity | I4: Unit_Price | J4: Payment_Method | K4: Region | L4: Customer_Segment | M4: Customer_Since | N4: Total_Amount | O4: Timestamp | P4: Today's Date | Q4: Customer Tenure | R4: Month End | S4: Month | T4: Product Frequency | U4: Customer Frequency | V4: Customer Abbreviation
A5: TRX0155 | B5: 45393 | C5: CUST023 | D5: Paul Baker | E5: P009 | F5: Monitor | G5: Electronics | H5: 3 | I5: 249.99 | J5: Cash | K5: Central | L5: Basic | M5: 44425 | N5: 749.97 | O5: =IF(A5="","",IF(O5=0,NOW(),O5)) -> 46301.614 | P5: =TODAY() -> 46302 | Q5: =DATEDIF(Sales_Data[[#This Row],[Customer_Since]],Sales_Data[[#This Row],[Date]],"d") -> 968 | R5: =EOMONTH(B5,0) -> 45412 | S5: =TEXT(B5,"mmm-yy") -> Apr-24 | T5: =COUNTIF(Sales_Data[Product_Name],F5) -> 26 | U5: =COUNTIF(Sales_Data[Customer_ID],C5) -> 8 | V5: =UPPER(LEFT(D5,1)&LEFT(MID(D5,FIND(" ",D5)+1,99),1)) -> PB
A6: TRX0023 | B6: 45396 | C6: CUST013 | D6: Joseph Jackson | E6: P009 | F6: Monitor | G6: Electronics | H6: 3 | I6: 249.99 | J6: Credit Card | K6: Central | L6: Premium | M6: 44575 | N6: 749.97 | O6: =IF(A6="","",IF(O6=0,NOW(),O6)) -> 46301.614 | P6: =TODAY() -> 46302 | Q6: =DATEDIF(Sales_Data[[#This Row],[Customer_Since]],Sales_Data[[#This Row],[Date]],"d") -> 821 | R6: =EOMONTH(B6,0) -> 45412 | S6: =TEXT(B6,"mmm-yy") -> Apr-24 | T6: =COUNTIF(Sales_Data[Product_Name],F6) -> 26 | U6: =COUNTIF(Sales_Data[Customer_ID],C6) -> 5 | V6: =UPPER(LEFT(D6,1)&LEFT(MID(D6,FIND(" ",D6)+1,99),1)) -> JJ
A7: TRX0139 | B7: 45399 | C7: CUST021 | D7: Kevin Scott | E7: P005 | F7: Blender | G7: Appliances | H7: 3 | I7: 59.99 | J7: PayPal | K7: South | L7: Standard | M7: 45262 | N7: 179.97 | O7: =IF(A7="","",IF(O7=0,NOW(),O7)) -> 46301.614 | P7: =TODAY() -> 46302 | Q7: =DATEDIF(Sales_Data[[#This Row],[Customer_Since]],Sales_Data[[#This Row],[Date]],"d") -> 137 | R7: =EOMONTH(B7,0) -> 45412 | S7: =TEXT(B7,"mmm-yy") -> Apr-24 | T7: =COUNTIF(Sales_Data[Product_Name],F7) -> 29 | U7: =COUNTIF(Sales_Data[Customer_ID],C7) -> 6 | V7: =UPPER(LEFT(D7,1)&LEFT(MID(D7,FIND(" ",D7)+1,99),1)) -> KS
A8: TRX0043 | B8: 45400 | C8: CUST046 | D8: Kathleen Bennett | E8: P005 | F8: Blender | G8: Appliances | H8: 3 | I8: 59.99 | J8: Cash | K8: North | L8: Premium | M8: 45114 | N8: 179.97 | O8: =IF(A8="","",IF(O8=0,NOW(),O8)) -> 46301.614 | P8: =TODAY() -> 46302 | Q8: =DATEDIF(Sales_Data[[#This Row],[Customer_Since]],Sales_Data[[#This Row],[Date]],"d") -> 286 | R8: =EOMONTH(B8,0) -> 45412 | S8: =TEXT(B8,"mmm-yy") -> Apr-24 | T8: =COUNTIF(Sales_Data[Product_Name],F8) -> 29 | U8: =COUNTIF(Sales_Data[Customer_ID],C8) -> 6 | V8: =UPPER(LEFT(D8,1)&LEFT(MID(D8,FIND(" ",D8)+1,99),1)) -> KB
A9: TRX0212 | B9: 45400 | C9: CUST003 | D9: Michael Brown | E9: P008 | F9: Bookshelf | G9: Furniture | H9: 5 | I9: 149.99 | J9: Credit Card | K9: North | L9: Premium | M9: 45295 | N9: 749.95 | O9: =IF(A9="","",IF(O9=0,NOW(),O9)) -> 46301.614 | P9: =TODAY() -> 46302 | Q9: =DATEDIF(Sales_Data[[#This Row],[Customer_Since]],Sales_Data[[#This Row],[Date]],"d") -> 105 | R9: =EOMONTH(B9,0) -> 45412 | S9: =TEXT(B9,"mmm-yy") -> Apr-24 | T9: =COUNTIF(Sales_Data[Product_Name],F9) -> 35 | U9: =COUNTIF(Sales_Data[Customer_ID],C9) -> 9 | V9: =UPPER(LEFT(D9,1)&LEFT(MID(D9,FIND(" ",D9)+1,99),1)) -> MB
A10: TRX0092 | B10: 45403 | C10: CUST024 | D10: Dorothy Nelson | E10: P005 | F10: Blender | G10: Appliances | H10: 2 | I10: 59.99 | J10: Cash | K10: West | L10: Standard | M10: 44746 | N10: 119.98 | O10: =IF(A10="","",IF(O10=0,NOW(),O10)) -> 46301.614 | P10: =TODAY() -> 46302 | Q10: =DATEDIF(Sales_Data[[#This Row],[Customer_Since]],Sales_Data[[#This Row],[Date]],"d") -> 657 | R10: =EOMONTH(B10,0) -> 45412 | S10: =TEXT(B10,"mmm-yy") -> Apr-24 | T10: =COUNTIF(Sales_Data[Product_Name],F10) -> 29 | U10: =COUNTIF(Sales_Data[Customer_ID],C10) -> 6 | V10: =UPPER(LEFT(D10,1)&LEFT(MID(D10,FIND(" ",D10)+1,99),1)) -> DN
A11: TRX0193 | B11: 45403 | C11: CUST024 | D11: Dorothy Nelson | E11: P003 | F11: Headphones | G11: Electronics | H11: 5 | I11: 149.99 | J11: Credit Card | K11: Central | L11: Standard | M11: 44418 | N11: 749.95 | O11: =IF(A11="","",IF(O11=0,NOW(),O11)) -> 46301.614 | P11: =TODAY() -> 46302 | Q11: =DATEDIF(Sales_Data[[#This Row],[Customer_Since]],Sales_Data[[#This Row],[Date]],"d") -> 985 | R11: =EOMONTH(B11,0) -> 45412 | S11: =TEXT(B11,"mmm-yy") -> Apr-24 | T11: =COUNTIF(Sales_Data[Product_Name],F11) -> 16 | U11: =COUNTIF(Sales_Data[Customer_ID],C11) -> 6 | V11: =UPPER(LEFT(D11,1)&LEFT(MID(D11,FIND(" ",D11)+1,99),1)) -> DN
A12: TRX0240 | B12: 45403 | C12: CUST017 | D12: Charles Allen | E12: P005 | F12: Blender | G12: Appliances | H12: 3 | I12: 59.99 | J12: Debit Card | K12: South | L12: Basic | M12: 45007 | N12: 179.97 | O12: =IF(A12="","",IF(O12=0,NOW(),O12)) -> 46301.614 | P12: =TODAY() -> 46302 | Q12: =DATEDIF(Sales_Data[[#This Row],[Customer_Since]],Sales_Data[[#This Row],[Date]],"d") -> 396 | R12: =EOMONTH(B12,0) -> 45412 | S12: =TEXT(B12,"mmm-yy") -> Apr-24 | T12: =COUNTIF(Sales_Data[Product_Name],F12) -> 29 | U12: =COUNTIF(Sales_Data[Customer_ID],C12) -> 9 | V12: =UPPER(LEFT(D12,1)&LEFT(MID(D12,FIND(" ",D12)+1,99),1)) -> CA
A13: TRX0135 | B13: 45405 | C13: CUST009 | D13: Robert Thomas | E13: P001 | F13: Laptop | G13: Electronics | H13: 3 | I13: 899.99 | J13: PayPal | K13: East | L13: Standard | M13: 45299 | N13: 2699.97 | O13: =IF(A13="","",IF(O13=0,NOW(),O13)) -> 46301.614 | P13: =TODAY() -> 46302 | Q13: =DATEDIF(Sales_Data[[#This Row],[Customer_Since]],Sales_Data[[#This Row],[Date]],"d") -> 106 | R13: =EOMONTH(B13,0) -> 45412 | S13: =TEXT(B13,"mmm-yy") -> Apr-24 | T13: =COUNTIF(Sales_Data[Product_Name],F13) -> 24 | U13: =COUNTIF(Sales_Data[Customer_ID],C13) -> 5 | V13: =UPPER(LEFT(D13,1)&LEFT(MID(D13,FIND(" ",D13)+1,99),1)) -> RT
A14: TRX0185 | B14: 45408 | C14: CUST026 | D14: Karen Hill | E14: P005 | F14: Blender | G14: Appliances | H14: 3 | I14: 59.99 | J14: Cash | K14: West | L14: Premium | M14: 45207 | N14: 179.97 | O14: =IF(A14="","",IF(O14=0,NOW(),O14)) -> 46301.614 | P14: =TODAY() -> 46302 | Q14: =DATEDIF(Sales_Data[[#This Row],[Customer_Since]],Sales_Data[[#This Row],[Date]],"d") -> 201 | R14: =EOMONTH(B14,0) -> 45412 | S14: =TEXT(B14,"mmm-yy") -> Apr-24 | T14: =COUNTIF(Sales_Data[Product_Name],F14) -> 29 | U14: =COUNTIF(Sales_Data[Customer_ID],C14) -> 8 | V14: =UPPER(LEFT(D14,1)&LEFT(MID(D14,FIND(" ",D14)+1,99),1)) -> KH
A15: TRX0138 | B15: 45408 | C15: CUST022 | D15: Susan Green | E15: P008 | F15: Bookshelf | G15: Furniture | H15: 1 | I15: 149.99 | J15: Credit Card | K15: West | L15: Standard | M15: 45103 | N15: 149.99 | O15: =IF(A15="","",IF(O15=0,NOW(),O15)) -> 46301.614 | P15: =TODAY() -> 46302 | Q15: =DATEDIF(Sales_Data[[#This Row],[Customer_Since]],Sales_Data[[#This Row],[Date]],"d") -> 305 | R15: =EOMONTH(B15,0) -> 45412 | S15: =TEXT(B15,"mmm-yy") -> Apr-24 | T15: =COUNTIF(Sales_Data[Product_Name],F15) -> 35 | U15: =COUNTIF(Sales_Data[Customer_ID],C15) -> 4 | V15: =UPPER(LEFT(D15,1)&LEFT(MID(D15,FIND(" ",D15)+1,99),1)) -> SG
A16: TRX0209 | B16: 45408 | C16: CUST046 | D16: Kathleen Bennett | E16: P008 | F16: Bookshelf | G16: Furniture | H16: 5 | I16: 149.99 | J16: Debit Card | K16: North | L16: Basic | M16: 44830 | N16: 749.95 | O16: =IF(A16="","",IF(O16=0,NOW(),O16)) -> 46301.614 | P16: =TODAY() -> 46302 | Q16: =DATEDIF(Sales_Data[[#This Row],[Customer_Since]],Sales_Data[[#This Row],[Date]],"d") -> 578 | R16: =EOMONTH(B16,0) -> 45412 | S16: =TEXT(B16,"mmm-yy") -> Apr-24 | T16: =COUNTIF(Sales_Data[Product_Name],F16) -> 35 | U16: =COUNTIF(Sales_Data[Customer_ID],C16) -> 6 | V16: =UPPER(LEFT(D16,1)&LEFT(MID(D16,FIND(" ",D16)+1,99),1)) -> KB
... A254: TRX0064 | B254: 45758 | C254: CUST031 | D254: Steven Turner | E254: P010 | F254: Keyboard | G254: Electronics | H254: 3 | I254: 89.99 | J254: Debit Card | K254: North | L254: Premium | M254: 44878 | N254: 269.97 | O254: =IF(A254="","",IF(O254=0,NOW(),O254)) -> 46301.614 | P254: =TODAY() -> 46302 | Q254: =DATEDIF(Sales_Data[[#This Row],[Customer_Since]],Sales_Data[[#This Row],[Date]],"d") -> 880 | R254: =EOMONTH(B254,0) -> 45777 | S254: =TEXT(B254,"mmm-yy") -> Apr-25 | T254: =COUNTIF(Sales_Data[Product_Name],F254) -> 34 | U254: =COUNTIF(Sales_Data[Customer_ID],C254) -> 6 | V254: =UPPER(LEFT(D254,1)&LEFT(MID(D254,FIND(" ",D254)+1,99),1)) -> ST

Sheet Analysis
A1: 📊 Data Intelligence Analysis
A3: 📊 KEY PERFORMANCE INDICATORS | D3: 🎯 KPI TARGETS | I3: 📋 LIST COMPARISON | M3: 🌍 REGIONAL SALES ANALYSIS | P3: 🎯 WHAT-IF ANALYSIS
A4: KPI | B4: Value | D4: KPI | E4: Actual | F4: Target | G4: Status | I4: Customer List 1 | J4: Customer List 2 | K4: Matching Name | M4: Region | N4: Total Revenue | P4: Item | Q4: Value
A5: Total Revenue | B5: =SUM('Raw Data'!N5:N254) -> 229192.47 | D5: Total Revenue | E5: =SUM('Raw Data'!N5:N254) -> 229192.47 | F5: 250000 | G5: =IF(F5>=G5,"▲ On Track","▼ Below Target") -> ▼ Below Target | I5: Paul Baker | J5: Kevin Scott | K5: {=_xlfn._xlws.FILTER(I5:I9,COUNTIF(J5:J9,I5:I9)>0,"No Match")} -> Paul Baker | M5: East | N5: =SUMIF('Raw Data'!$K$5:$K$254,M5,'Raw Data'!$N$5:$N$254) -> 59288.39 | P5: Current Revenue | Q5: =SUM('Raw Data'!N5:N254) -> 229192.47
A6: Total Transactions | B6: =COUNTA('Raw Data'!A5:A254) -> 250 | D6: Total Transactions | E6: =COUNTA('Raw Data'!A5:A254) -> 250 | F6: 300 | G6: =IF(F6>=G6,"▲ On Track","▼ Below Target") -> ▼ Below Target | I6: Kevin Scott | J6: Susan Green | K6: Kevin Scott | M6: North | N6: =SUMIF('Raw Data'!$K$5:$K$254,M6,'Raw Data'!$N$5:$N$254) -> 50808.31 | P6: Growth % | Q6: 0.090786272
A7: Total Units Sold | B7: =SUM('Raw Data'!H5:H254) -> 753 | D7: Total Units Sold | E7: =SUM('Raw Data'!H5:H254) -> 753 | F7: 800 | G7: =IF(F7>=G7,"▲ On Track","▼ Below Target") -> ▼ Below Target | I7: Michael Brown | J7: Dorothy Nelson | K7: Dorothy Nelson | M7: West | N7: =SUMIF('Raw Data'!$K$5:$K$254,M7,'Raw Data'!$N$5:$N$254) -> 41408.68 | P7: Projected Revenue | Q7: =Q5*(1+Q6) -> 250000
A8: Total Customers | B8: =COUNTA(_xlfn.UNIQUE('Raw Data'!C5:C254)) -> 50 | D8: Total Customers | E8: =COUNTA(_xlfn.UNIQUE('Raw Data'!C5:C254)) -> 50 | F8: 60 | G8: =IF(F8>=G8,"▲ On Track","▼ Below Target") -> ▼ Below Target | I8: Dorothy Nelson | J8: Paul Baker | M8: Central | N8: =SUMIF('Raw Data'!$K$5:$K$254,M8,'Raw Data'!$N$5:$N$254) -> 41288.34
A9: Average Order Value | B9: =AVERAGE('Raw Data'!N5:N254) -> 916.76988 | D9: Average Order Value | E9: =AVERAGE('Raw Data'!N5:N254) -> 916.76988 | F9: 1000 | G9: =IF(F9>=G9,"▲ On Track","▼ Below Target") -> ▼ Below Target | I9: Robert Thomas | J9: Sarah Wilson | M9: South | N9: =SUMIF('Raw Data'!$K$5:$K$254,M9,'Raw Data'!$N$5:$N$254) -> 36398.75 | P9: 🎯 Scenario Manager
P10: Scenario | Q10: Growth% | R10: Projected Revenue
A11: 👑 HIGH-VALUE CUSTOMER ANALYSIS | F11: 📦 PRODUCT ANALYSIS | K11: 📈 LINEAR REGRESSION | P11: Base | Q11: 0 | R11: =$Q$5*(1+Q11) -> 229192.47
A12: Customer ID | B12: Customer Name | C12: Total Revenue | D12: Transactions | F12: Product | G12: Units Sold | H12: Revenue | I12: Transactions | K12: Regression Statistics | P12: Growth 10% | Q12: 0.1 | R12: =$Q$5*(1+Q12) -> 252111.72
A13: {=_xlfn.UNIQUE('Raw Data'!C5:C254)} -> CUST023 | B13: {=_xlfn.XLOOKUP(_xlfn.ANCHORARRAY(A13),'Raw Data'!C5:C254,'Raw Data'!D5:D254)} -> Paul Baker | C13: {=SUMIF('Raw Data'!C5:C254,_xlfn.ANCHORARRAY(A13),'Raw Data'!N5:N254)} -> 8309.74 | D13: {=COUNTIF('Raw Data'!C5:C254,_xlfn.ANCHORARRAY(A13))} -> 8 | F13: {=_xlfn.UNIQUE('Raw Data'!F5:F254)} -> Monitor | G13: =SUMIF('Raw Data'!$F$5:$F$254,F13,'Raw Data'!$H$5:$H$254) -> 88 | H13: =SUMIF('Raw Data'!$F$5:$F$254,F13,'Raw Data'!$N$5:$N$254) -> 21999.12 | I13: =COUNTIF('Raw Data'!$F$5:$F$254,F13) -> 26 | K13: Multiple R | L13: 0.015347018 | P13: Growth 20% | Q13: 0.2 | R13: =$Q$5*(1+Q13) -> 275030.96
A14: CUST013 | B14: Joseph Jackson | C14: 6949.84 | D14: 5 | F14: Blender | G14: =SUMIF('Raw Data'!$F$5:$F$254,F14,'Raw Data'!$H$5:$H$254) -> 87 | H14: =SUMIF('Raw Data'!$F$5:$F$254,F14,'Raw Data'!$N$5:$N$254) -> 5219.13 | I14: =COUNTIF('Raw Data'!$F$5:$F$254,F14) -> 29 | K14: R Square | L14: 0.00023553098
A15: CUST021 | B15: Kevin Scott | C15: 3259.87 | D15: 6 | F15: Bookshelf | G15: =SUMIF('Raw Data'!$F$5:$F$254,F15,'Raw Data'!$H$5:$H$254) -> 102 | H15: =SUMIF('Raw Data'!$F$5:$F$254,F15,'Raw Data'!$N$5:$N$254) -> 15298.98 | I15: =COUNTIF('Raw Data'!$F$5:$F$254,F15) -> 35 | K15: Adjusted R Square | L15: -0.0037957774
A16: CUST046 | B16: Kathleen Bennett | C16: 4309.81 | D16: 6 | F16: Headphones | G16: =SUMIF('Raw Data'!$F$5:$F$254,F16,'Raw Data'!$H$5:$H$254) -> 47 | H16: =SUMIF('Raw Data'!$F$5:$F$254,F16,'Raw Data'!$N$5:$N$254) -> 7049.53 | I16: =COUNTIF('Raw Data'!$F$5:$F$254,F16) -> 16 | K16: Standard Error | L16: 1034.4107
A17: CUST003 | B17: Michael Brown | C17: 6169.74 | D17: 9 | F17: Laptop | G17: =SUMIF('Raw Data'!$F$5:$F$254,F17,'Raw Data'!$H$5:$H$254) -> 75 | H17: =SUMIF('Raw Data'!$F$5:$F$254,F17,'Raw Data'!$N$5:$N$254) -> 67499.25 | I17: =COUNTIF('Raw Data'!$F$5:$F$254,F17) -> 24 | K17: Observations | L17: 250
A18: CUST024 | B18: Dorothy Nelson | C18: 8269.79 | D18: 6 | F18: Smartphone | G18: =SUMIF('Raw Data'!$F$5:$F$254,F18,'Raw Data'!$H$5:$H$254) -> 96 | H18: =SUMIF('Raw Data'!$F$5:$F$254,F18,'Raw Data'!$N$5:$N$254) -> 67199.04 | I18: =COUNTIF('Raw Data'!$F$5:$F$254,F18) -> 31
A19: CUST017 | B19: Charles Allen | C19: 5089.73 | D19: 9 | F19: Desk | G19: =SUMIF('Raw Data'!$F$5:$F$254,F19,'Raw Data'!$H$5:$H$254) -> 78 | H19: =SUMIF('Raw Data'!$F$5:$F$254,F19,'Raw Data'!$N$5:$N$254) -> 23399.22 | I19: =COUNTIF('Raw Data'!$F$5:$F$254,F19) -> 26 | K19: ANOVA
A20: CUST009 | B20: Robert Thomas | C20: 3509.9 | D20: 5 | F20: Coffee Maker | G20: =SUMIF('Raw Data'!$F$5:$F$254,F20,'Raw Data'!$H$5:$H$254) -> 39 | H20: =SUMIF('Raw Data'!$F$5:$F$254,F20,'Raw Data'!$N$5:$N$254) -> 3119.61 | I20: =COUNTIF('Raw Data'!$F$5:$F$254,F20) -> 14 | L20: df | M20: SS | N20: MS | O20: F | P20: Significance F
A21: CUST026 | B21: Karen Hill | C21: 8009.77 | D21: 8 | F21: Keyboard | G21: =SUMIF('Raw Data'!$F$5:$F$254,F21,'Raw Data'!$H$5:$H$254) -> 89 | H21: =SUMIF('Raw Data'!$F$5:$F$254,F21,'Raw Data'!$N$5:$N$254) -> 8009.11 | I21: =COUNTIF('Raw Data'!$F$5:$F$254,F21) -> 34 | K21: Regression | L21: 1 | M21: 62515.548 | N21: 62515.548 | O21: 0.058425443 | P21: 0.80920187
A22: CUST022 | B22: Susan Green | C22: 1979.89 | D22: 4 | F22: Office Chair | G22: =SUMIF('Raw Data'!$F$5:$F$254,F22,'Raw Data'!$H$5:$H$254) -> 52 | H22: =SUMIF('Raw Data'!$F$5:$F$254,F22,'Raw Data'!$N$5:$N$254) -> 10399.48 | I22: =COUNTIF('Raw Data'!$F$5:$F$254,F22) -> 15 | K22: Residual | L22: 248 | M22: 2.6536138e+08 | N22: 1070005.5
A23: CUST041 | B23: Peter Richardson | C23: 5949.85 | D23: 5 | K23: Total | L23: 249 | M23: 2.6542389e+08
A24: CUST043 | B24: Dennis Gray | C24: 479.92 | D24: 2 | F24: 👥 CUSTOMER SEGMENT ANALYSIS
A25: CUST038 | B25: Michelle Rogers | C25: 4199.94 | D25: 2 | F25: Segment | G25: Revenue
A26: CUST027 | B26: George Adams | C26: 3779.93 | D26: 3 | F26: Premium | G26: =SUMIF('Raw Data'!$L$5:$L$254,F26,'Raw Data'!$N$5:$N$254) -> 84657.12
A27: CUST025 | B27: Mark Carter | C27: 15659.65 | D27: 12 | F27: Standard | G27: =SUMIF('Raw Data'!$L$5:$L$254,F27,'Raw Data'!$N$5:$N$254) -> 82357.54
A28: CUST010 | B28: Maria Garcia | C28: 1909.93 | D28: 4 | F28: Basic | G28: =SUMIF('Raw Data'!$L$5:$L$254,F28,'Raw Data'!$N$5:$N$254) -> 62177.81
A29: CUST048 | B29: Virginia Sanders | C29: 4789.79 | D29: 6
A30: CUST018 | B30: Barbara Young | C30: 10649.8 | D30: 5 | F30: 🔎 FILTER — PREMIUM CUSTOMERS (Multi-Value Returns)
A31: CUST012 | B31: Patricia Moore | C31: 9799.73 | D31: 8
A32: CUST044 | B32: Cynthia Price | C32: 3769.83 | D32: 5 | F32: Region | G32: East | I32: Customer Segment | J32: Premium
A33: CUST036 | B33: Nancy Collins | C33: 4189.77 | D33: 6
A34: CUST014 | B34: Linda Martin | C34: 1289.9 | D34: 4 | F34: Transaction_ID | G34: Date | H34: Customer_ID | I34: Customer_Name | J34: Product_ID | K34: Product_Name | L34: Category | M34: Quantity | N34: Unit_Price | O34: Payment_Method | P34: Region | Q34: Customer_Segment | R34: Customer_Since | S34: Total_Amount
A35: CUST030 | B35: Helen Roberts | C35: 6459.79 | D35: 7 | F35: {=_xlfn._xlws.FILTER('Raw Data'!A5:N254,('Raw Data'!K5:K254=G32)*('Raw Data'!L5:L254=J32),"No matching records")} -> TRX0235 | G35: 45424 | H35: CUST014 | I35: Linda Martin | J35: P004 | K35: Coffee Maker | L35: Appliances | M35: 3 | N35: 79.99 | O35: PayPal | P35: East | Q35: Premium | R35: 45012 | S35: 239.97
A36: CUST029 | B36: Edward Mitchell | C36: 11919.77 | D36: 6 | F36: TRX0220 | G36: 45450 | H36: CUST003 | I36: Michael Brown | J36: P008 | K36: Bookshelf | L36: Furniture | M36: 2 | N36: 149.99 | O36: Cash | P36: East | Q36: Premium | R36: 44645 | S36: 299.98
A37: CUST006 | B37: Lisa Anderson | C37: 2039.8 | D37: 5 | F37: TRX0044 | G37: 45459 | H37: CUST029 | I37: Edward Mitchell | J37: P001 | K37: Laptop | L37: Electronics | M37: 5 | N37: 899.99 | O37: PayPal | P37: East | Q37: Premium | R37: 45278 | S37: 4499.95
A38: CUST002 | B38: Emma Wilson | C38: 1229.88 | D38: 5 | F38: TRX0184 | G38: 45471 | H38: CUST046 | I38: Kathleen Bennett | J38: P002 | K38: Smartphone | L38: Electronics | M38: 3 | N38: 699.99 | O38: Credit Card | P38: East | Q38: Premium | R38: 45102 | S38: 2099.97
A39: CUST031 | B39: Steven Turner | C39: 2649.83 | D39: 6 | F39: TRX0104 | G39: 45471 | H39: CUST012 | I39: Patricia Moore | J39: P001 | K39: Laptop | L39: Electronics | M39: 4 | N39: 899.99 | O39: Credit Card | P39: East | Q39: Premium | R39: 44993 | S39: 3599.96
A40: CUST008 | B40: Jennifer Taylor | C40: 4739.85 | D40: 4 | F40: TRX0113 | G40: 45481 | H40: CUST003 | I40: Michael Brown | J40: P002 | K40: Smartphone | L40: Electronics | M40: 2 | N40: 699.99 | O40: PayPal | P40: East | Q40: Premium | R40: 45389 | S40: 1399.98
A41: CUST035 | B41: Harry Morgan | C41: 5519.89 | D41: 4 | F41: TRX0075 | G41: 45517 | H41: CUST020 | I41: Margaret Wright | J41: P009 | K41: Monitor | L41: Electronics | M41: 5 | N41: 249.99 | O41: PayPal | P41: East | Q41: Premium | R41: 44782 | S41: 1249.95
...

Sheet Pivot Analysis
A1: 📊 PIVOT ANALYSIS
A3: 🌍 REGIONAL SALES ANALYSIS | D3: 👥 CUSTOMER SEGMENT ANALYSIS | H3: 📦 PRODUCT PERFORMANCE
A4: Region | B4: Sum of Total_Amount | D4: Customer Segment | E4: Sum of Total_Amount | F4: Count of Transaction_ID | H4: Product Name | I4: Sum of Quantity | J4: Sum of Total_Amount
A5: Central | B5: 41288.34 | D5: Basic | E5: 62177.81 | F5: 74 | H5: Blender | I5: 87 | J5: 5219.13
A6: East | B6: 59288.39 | D6: Premium | E6: 84657.12 | F6: 95 | H6: Bookshelf | I6: 102 | J6: 15298.98
A7: North | B7: 50808.31 | D7: Standard | E7: 82357.54 | F7: 81 | H7: Coffee Maker | I7: 39 | J7: 3119.61
A8: South | B8: 36398.75 | D8: Grand Total | E8: 229192.47 | F8: 250 | H8: Desk | I8: 78 | J8: 23399.22
A9: West | B9: 41408.68 | H9: Headphones | I9: 47 | J9: 7049.53
A10: Grand Total | B10: 229192.47 | H10: Keyboard | I10: 89 | J10: 8009.11
D11: 💳 PAYMENT METHOD ANALYSIS | H11: Laptop | I11: 75 | J11: 67499.25
D12: Payment Method | E12: Count of Transaction_ID | F12: Sum of Total_Amount | H12: Monitor | I12: 88 | J12: 21999.12
D13: Cash | E13: 76 | F13: 57427.79 | H13: Office Chair | I13: 52 | J13: 10399.48
D14: Credit Card | E14: 68 | F14: 61447.96 | H14: Smartphone | I14: 96 | J14: 67199.04
D15: Debit Card | E15: 54 | F15: 52118.31 | H15: Grand Total | I15: 753 | J15: 229192.47
D16: PayPal | E16: 52 | F16: 58198.41
D17: Grand Total | E17: 250 | F17: 229192.47

Sheet Dashboard
A1: 📊 Customer Transaction Dashboard
A6: 💰 Total Revenue | F6: 🧾 Total Transactions | K6: 📦 Total Units Sold | P6: 👥 Total Customers | U6: 💵 Average Order Value
A7: =SUM('Raw Data'!N5:N254) -> 229192.47 | F7: =COUNTA('Raw Data'!A5:A254) -> 250 | K7: =SUM('Raw Data'!H5:H254) -> 753 | P7: =COUNTA(_xlfn.UNIQUE('Raw Data'!C5:C254)) -> 50 | U7: =AVERAGE('Raw Data'!N5:N254) -> 916.76988
A9: 🎛️ FILTER & SLICERS | P9: 💡 KEY INSIGHTS
